Workbook

Sheet doses_results
B1: ...1 | C1: Variable | D1: Beta | E1: CI_Lower | F1: CI_Upper | G1: AIC | H1: BIC | I1: dose | J1: model | K1: effects | L1: Beta [CI}
A2: 1 | B2: (Intercept) | C2: (Intercept) | D2: 82.647134 | E2: 82.47111 | F2: 82.823158 | G2: 1205.2911 | H2: 1299.026 | I2: First | J2: Simple | K2: Fixed | L2: =TEXT(ROUND(D2,2),"0.00") & "[" & TEXT(ROUND(E2,2),"0.00") & "," & TEXT(ROUND(F2,2),"0.00") & "]" -> 82.65[82.47,82.82]
A3: 2 | B3: Pop_per_km2 | C3: Pop_per_km2 | D3: -0.049447362 | E3: -0.50673387 | F3: 0.40783915 | G3: 1205.2911 | H3: 1299.026 | I3: First | J3: Simple | K3: Fixed | L3: =TEXT(ROUND(D3,2),"0.00") & "[" & TEXT(ROUND(E3,2),"0.00") & "," & TEXT(ROUND(F3,2),"0.00") & "]" -> -0.05[-0.51,0.41] | P3: {=_xlfn.UNIQUE(C2:C322)} -> (Intercept) | R3: (Intercept)
A4: 3 | B4: prop_travelling_to_work | C4: prop_travelling_to_work | D4: -0.10442816 | E4: -1.1357717 | F4: 0.92691537 | G4: 1205.2911 | H4: 1299.026 | I4: First | J4: Simple | K4: Fixed | L4: =TEXT(ROUND(D4,2),"0.00") & "[" & TEXT(ROUND(E4,2),"0.00") & "," & TEXT(ROUND(F4,2),"0.00") & "]" -> -0.10[-1.14,0.93] | P4: Pop_per_km2 | R4: Pop_per_km2
A5: 4 | B5: prop_not_in_work | C5: prop_not_in_work | D5: -0.87895831 | E5: -2.146248 | F5: 0.38833139 | G5: 1205.2911 | H5: 1299.026 | I5: First | J5: Simple | K5: Fixed | L5: =TEXT(ROUND(D5,2),"0.00") & "[" & TEXT(ROUND(E5,2),"0.00") & "," & TEXT(ROUND(F5,2),"0.00") & "]" -> -0.88[-2.15,0.39] | P5: prop_travelling_to_work | R5: prop_travelling_to_work
A6: 5 | B6: prop_all_other_white | C6: prop_all_other_white | D6: -2.627491 | E6: -2.9737799 | F6: -2.281202 | G6: 1205.2911 | H6: 1299.026 | I6: First | J6: Simple | K6: Fixed | L6: =TEXT(ROUND(D6,2),"0.00") & "[" & TEXT(ROUND(E6,2),"0.00") & "," & TEXT(ROUND(F6,2),"0.00") & "]" -> -2.63[-2.97,-2.28] | P6: prop_not_in_work | R6: prop_not_in_work
A7: 6 | B7: prop_mixed_multiple | C7: prop_mixed_multiple | D7: -0.26134594 | E7: -0.56303848 | F7: 0.040346591 | G7: 1205.2911 | H7: 1299.026 | I7: First | J7: Simple | K7: Fixed | L7: =TEXT(ROUND(D7,2),"0.00") & "[" & TEXT(ROUND(E7,2),"0.00") & "," & TEXT(ROUND(F7,2),"0.00") & "]" -> -0.26[-0.56,0.04] | P7: prop_all_other_white | R7: prop_all_other_white
A8: 7 | B8: prop_asian | C8: prop_asian | D8: -0.46335369 | E8: -0.75342429 | F8: -0.1732831 | G8: 1205.2911 | H8: 1299.026 | I8: First | J8: Simple | K8: Fixed | L8: =TEXT(ROUND(D8,2),"0.00") & "[" & TEXT(ROUND(E8,2),"0.00") & "," & TEXT(ROUND(F8,2),"0.00") & "]" -> -0.46[-0.75,-0.17] | P8: prop_mixed_multiple | R8: prop_mixed_multiple
A9: 8 | B9: prop_black_afr_car | C9: prop_black_afr_car | D9: -0.8037181 | E9: -1.2267465 | F9: -0.38068968 | G9: 1205.2911 | H9: 1299.026 | I9: First | J9: Simple | K9: Fixed | L9: =TEXT(ROUND(D9,2),"0.00") & "[" & TEXT(ROUND(E9,2),"0.00") & "," & TEXT(ROUND(F9,2),"0.00") & "]" -> -0.80[-1.23,-0.38] | P9: prop_asian | R9: prop_asian
A10: 9 | B10: prop_other | C10: prop_other | D10: -0.01024721 | E10: -0.41320278 | F10: 0.39270836 | G10: 1205.2911 | H10: 1299.026 | I10: First | J10: Simple | K10: Fixed | L10: =TEXT(ROUND(D10,2),"0.00") & "[" & TEXT(ROUND(E10,2),"0.00") & "," & TEXT(ROUND(F10,2),"0.00") & "]" -> -0.01[-0.41,0.39] | P10: prop_black_afr_car | R10: prop_black_afr_car
A11: 10 | B11: IMD_Average_score | C11: IMD_Average_score | D11: 0.25236997 | E11: -1.1863091 | F11: 1.691049 | G11: 1205.2911 | H11: 1299.026 | I11: First | J11: Simple | K11: Fixed | L11: =TEXT(ROUND(D11,2),"0.00") & "[" & TEXT(ROUND(E11,2),"0.00") & "," & TEXT(ROUND(F11,2),"0.00") & "]" -> 0.25[-1.19,1.69] | P11: prop_other | R11: prop_other
A12: 11 | B12: prop_o65 | C12: prop_o65 | D12: 0.63029212 | E12: -0.26552558 | F12: 1.5261098 | G12: 1205.2911 | H12: 1299.026 | I12: First | J12: Simple | K12: Fixed | L12: =TEXT(ROUND(D12,2),"0.00") & "[" & TEXT(ROUND(E12,2),"0.00") & "," & TEXT(ROUND(F12,2),"0.00") & "]" -> 0.63[-0.27,1.53] | P12: IMD_Average_score | R12: IMD_Average_score
A13: 12 | B13: prop_u25 | C13: prop_u25 | D13: -1.2889942 | E13: -1.9296717 | F13: -0.64831662 | G13: 1205.2911 | H13: 1299.026 | I13: First | J13: Simple | K13: Fixed | L13: =TEXT(ROUND(D13,2),"0.00") & "[" & TEXT(ROUND(E13,2),"0.00") & "," & TEXT(ROUND(F13,2),"0.00") & "]" -> -1.29[-1.93,-0.65] | P13: prop_o65 | R13: prop_o65
A14: 13 | B14: Median_annual_income | C14: Median_annual_income | D14: -0.27808149 | E14: -0.60156863 | F14: 0.045405655 | G14: 1205.2911 | H14: 1299.026 | I14: First | J14: Simple | K14: Fixed | L14: =TEXT(ROUND(D14,2),"0.00") & "[" & TEXT(ROUND(E14,2),"0.00") & "," & TEXT(ROUND(F14,2),"0.00") & "]" -> -0.28[-0.60,0.05] | P14: prop_u25 | R14: prop_u25
A15: 14 | B15: Other_proportion | C15: Other_proportion | D15: -0.33739161 | E15: -0.61530973 | F15: -0.059473489 | G15: 1205.2911 | H15: 1299.026 | I15: First | J15: Simple | K15: Fixed | L15: =TEXT(ROUND(D15,2),"0.00") & "[" & TEXT(ROUND(E15,2),"0.00") & "," & TEXT(ROUND(F15,2),"0.00") & "]" -> -0.34[-0.62,-0.06] | P15: Median_annual_income | R15: Median_annual_income
... A35: 34 | B35: IMD_Average_score1 | C35: IMD_Average_score | D35: 0.10894829 | E35: -1.3636584 | F35: 1.581555 | G35: 1219.929 | H35: 1313.6638 | I35: Second | J35: Simple | K35: Fixed | L35: =TEXT(ROUND(D35,2),"0.00") & "[" & TEXT(ROUND(E35,2),"0.00") & "," & TEXT(ROUND(F35,2),"0.00") & "]" -> 0.11[-1.36,1.58] | P35: ASC_rapid_testing | R35: ASC_rapid_testing
A36: 35 | B36: prop_o651 | C36: prop_o65 | D36: 0.7620963 | E36: -0.15484702 | F36: 1.6790396 | G36: 1219.929 | H36: 1313.6638 | I36: Second | J36: Simple | K36: Fixed | L36: =TEXT(ROUND(D36,2),"0.00") & "[" & TEXT(ROUND(E36,2),"0.00") & "," & TEXT(ROUND(F36,2),"0.00") & "]" -> 0.76[-0.15,1.68]
A37: 36 | B37: prop_u251 | C37: prop_u25 | D37: -1.4908372 | E37: -2.1466235 | F37: -0.83505085 | G37: 1219.929 | H37: 1313.6638 | I37: Second | J37: Simple | K37: Fixed | L37: =TEXT(ROUND(D37,2),"0.00") & "[" & TEXT(ROUND(E37,2),"0.00") & "," & TEXT(ROUND(F37,2),"0.00") & "]" -> -1.49[-2.15,-0.84]
A38: 37 | B38: Median_annual_income1 | C38: Median_annual_income | D38: -0.24256383 | E38: -0.5736796 | F38: 0.088551951 | G38: 1219.929 | H38: 1313.6638 | I38: Second | J38: Simple | K38: Fixed | L38: =TEXT(ROUND(D38,2),"0.00") & "[" & TEXT(ROUND(E38,2),"0.00") & "," & TEXT(ROUND(F38,2),"0.00") & "]" -> -0.24[-0.57,0.09]
A39: 38 | B39: Other_proportion1 | C39: Other_proportion | D39: -0.36167225 | E39: -0.64614438 | F39: -0.077200129 | G39: 1219.929 | H39: 1313.6638 | I39: Second | J39: Simple | K39: Fixed | L39: =TEXT(ROUND(D39,2),"0.00") & "[" & TEXT(ROUND(E39,2),"0.00") & "," & TEXT(ROUND(F39,2),"0.00") & "]" -> -0.36[-0.65,-0.08]
A40: 39 | B40: unringfenced_percapita1 | C40: unringfenced_percapita | D40: -0.48058118 | E40: -0.79423878 | F40: -0.16692358 | G40: 1219.929 | H40: 1313.6638 | I40: Second | J40: Simple | K40: Fixed | L40: =TEXT(ROUND(D40,2),"0.00") & "[" & TEXT(ROUND(E40,2),"0.00") & "," & TEXT(ROUND(F40,2),"0.00") & "]" -> -0.48[-0.79,-0.17]
A41: 40 | B41: ASC_infection_control_fund_percapita1 | C41: ASC_infection_control_fund_percapita | D41: -0.25038258 | E41: -0.53755957 | F41: 0.036794406 | G41: 1219.929 | H41: 1313.6638 | I41: Second | J41: Simple | K41: Fixed | L41: =TEXT(ROUND(D41,2),"0.00") & "[" & TEXT(ROUND(E41,2),"0.00") & "," & TEXT(ROUND(F41,2),"0.00") & "]" -> -0.25[-0.54,0.04]
A42: 41 | B42: contain_outbreak_management_percapita1 | C42: contain_outbreak_management_percapita | D42: -0.61820338 | E42: -0.99987636 | F42: -0.23653041 | G42: 1219.929 | H42: 1313.6638 | I42: Second | J42: Simple | K42: Fixed | L42: =TEXT(ROUND(D42,2),"0.00") & "[" & TEXT(ROUND(E42,2),"0.00") & "," & TEXT(ROUND(F42,2),"0.00") & "]" -> -0.62[-1.00,-0.24]
A43: 42 | B43: Income_score1 | C43: Income_score | D43: -1.5156281 | E43: -3.2471263 | F43: 0.21587004 | G43: 1219.929 | H43: 1313.6638 | I43: Second | J43: Simple | K43: Fixed | L43: =TEXT(ROUND(D43,2),"0.00") & "[" & TEXT(ROUND(E43,2),"0.00") & "," & TEXT(ROUND(F43,2),"0.00") & "]" -> -1.52[-3.25,0.22]
A44: 43 | B44: Employment_score1 | C44: Employment_score | D44: 1.3681037 | E44: -0.32474655 | F44: 3.0609539 | G44: 1219.929 | H44: 1313.6638 | I44: Second | J44: Simple | K44: Fixed | L44: =TEXT(ROUND(D44,2),"0.00") & "[" & TEXT(ROUND(E44,2),"0.00") & "," & TEXT(ROUND(F44,2),"0.00") & "]" -> 1.37[-0.32,3.06]
A45: 44 | B45: Education_Skills_and_Training_score1 | C45: Education_Skills_and_Training_score | D45: -0.61362817 | E45: -1.1682395 | F45: -0.059016797 | G45: 1219.929 | H45: 1313.6638 | I45: Second | J45: Simple | K45: Fixed | L45: =TEXT(ROUND(D45,2),"0.00") & "[" & TEXT(ROUND(E45,2),"0.00") & "," & TEXT(ROUND(F45,2),"0.00") & "]" -> -0.61[-1.17,-0.06]
A46: 45 | B46: Health_Deprivation_and_Disability_score1 | C46: Health_Deprivation_and_Disability_score | D46: -0.43410511 | E46: -1.0612865 | F46: 0.19307632 | G46: 1219.929 | H46: 1313.6638 | I46: Second | J46: Simple | K46: Fixed | L46: =TEXT(ROUND(D46,2),"0.00") & "[" & TEXT(ROUND(E46,2),"0.00") & "," & TEXT(ROUND(F46,2),"0.00") & "]" -> -0.43[-1.06,0.19]
A47: 46 | B47: Crime_score1 | C47: Crime_score | D47: -0.32055701 | E47: -0.69417775 | F47: 0.05306373 | G47: 1219.929 | H47: 1313.6638 | I47: Second | J47: Simple | K47: Fixed | L47: =TEXT(ROUND(D47,2),"0.00") & "[" & TEXT(ROUND(E47,2),"0.00") & "," & TEXT(ROUND(F47,2),"0.00") & "]" -> -0.32[-0.69,0.05]
... A73: 72 | B73: Living_Environment_score2 | C73: Living_Environment_score | D73: -0.81006566 | E73: -1.2290328 | F73: -0.39109849 | G73: 1357.8897 | H73: 1451.6245 | I73: Third | J73: Simple | K73: Fixed | L73: =TEXT(ROUND(D73,2),"0.00") & "[" & TEXT(ROUND(E73,2),"0.00") & "," & TEXT(ROUND(F73,2),"0.00") & "]" -> -0.81[-1.23,-0.39]
A74: 73 | B74: 1 | C74: (Intercept) | D74: 82.653839 | E74: 82.268366 | F74: 83.039312 | G74: 1245.6421 | H74: 1343.1263 | I74: First | J74: Simple | K74: Random | L74: =TEXT(ROUND(D74,2),"0.00") & "[" & TEXT(ROUND(E74,2),"0.00") & "," & TEXT(ROUND(F74,2),"0.00") & "]" -> 82.65[82.27,83.04]
A75: 74 | B75: 2 | C75: Pop_per_km2 | D75: -0.10387342 | E75: -0.56469385 | F75: 0.35694702 | G75: 1245.6421 | H75: 1343.1263 | I75: First | J75: Simple | K75: Random | L75: =TEXT(ROUND(D75,2),"0.00") & "[" & TEXT(ROUND(E75,2),"0.00") & "," & TEXT(ROUND(F75,2),"0.00") & "]" -> -0.10[-0.56,0.36]
A76: 75 | B76: 3 | C76: prop_travelling_to_work | D76: 0.037361524 | E76: -1.0000186 | F76: 1.0747417 | G76: 1245.6421 | H76: 1343.1263 | I76: First | J76: Simple | K76: Random | L76: =TEXT(ROUND(D76,2),"0.00") & "[" & TEXT(ROUND(E76,2),"0.00") & "," & TEXT(ROUND(F76,2),"0.00") & "]" -> 0.04[-1.00,1.07]
A77: 76 | B77: 4 | C77: prop_not_in_work | D77: -0.74900911 | E77: -2.0364899 | F77: 0.53847168 | G77: 1245.6421 | H77: 1343.1263 | I77: First | J77: Simple | K77: Random | L77: =TEXT(ROUND(D77,2),"0.00") & "[" & TEXT(ROUND(E77,2),"0.00") & "," & TEXT(ROUND(F77,2),"0.00") & "]" -> -0.75[-2.04,0.54]
A78: 77 | B78: 5 | C78: prop_all_other_white | D78: -2.6170003 | E78: -2.9660744 | F78: -2.2679261 | G78: 1245.6421 | H78: 1343.1263 | I78: First | J78: Simple | K78: Random | L78: =TEXT(ROUND(D78,2),"0.00") & "[" & TEXT(ROUND(E78,2),"0.00") & "," & TEXT(ROUND(F78,2),"0.00") & "]" -> -2.62[-2.97,-2.27]
A79: 78 | B79: 6 | C79: prop_mixed_multiple | D79: -0.24877427 | E79: -0.54922017 | F79: 0.051671634 | G79: 1245.6421 | H79: 1343.1263 | I79: First | J79: Simple | K79: Random | L79: =TEXT(ROUND(D79,2),"0.00") & "[" & TEXT(ROUND(E79,2),"0.00") & "," & TEXT(ROUND(F79,2),"0.00") & "]" -> -0.25[-0.55,0.05]
A80: 79 | B80: 7 | C80: prop_asian | D80: -0.44847907 | E80: -0.73832536 | F80: -0.15863278 | G80: 1245.6421 | H80: 1343.1263 | I80: First | J80: Simple | K80: Random | L80: =TEXT(ROUND(D80,2),"0.00") & "[" & TEXT(ROUND(E80,2),"0.00") & "," & TEXT(ROUND(F80,2),"0.00") & "]" -> -0.45[-0.74,-0.16]
A81: 80 | B81: 8 | C81: prop_black_afr_car | D81: -0.81217667 | E81: -1.237178 | F81: -0.38717532 | G81: 1245.6421 | H81: 1343.1263 | I81: First | J81: Simple | K81: Random | L81: =TEXT(ROUND(D81,2),"0.00") & "[" & TEXT(ROUND(E81,2),"0.00") & "," & TEXT(ROUND(F81,2),"0.00") & "]" -> -0.81[-1.24,-0.39]
A82: 81 | B82: 9 | C82: prop_other | D82: -0.027070938 | E82: -0.43265473 | F82: 0.37851285 | G82: 1245.6421 | H82: 1343.1263 | I82: First | J82: Simple | K82: Random | L82: =TEXT(ROUND(D82,2),"0.00") & "[" & TEXT(ROUND(E82,2),"0.00") & "," & TEXT(ROUND(F82,2),"0.00") & "]" -> -0.03[-0.43,0.38]
A83: 82 | B83: 10 | C83: IMD_Average_score | D83: 0.25701592 | E83: -1.181804 | F83: 1.6958359 | G83: 1245.6421 | H83: 1343.1263 | I83: First | J83: Simple | K83: Random | L83: =TEXT(ROUND(D83,2),"0.00") & "[" & TEXT(ROUND(E83,2),"0.00") & "," & TEXT(ROUND(F83,2),"0.00") & "]" -> 0.26[-1.18,1.70]
A84: 83 | B84: 11 | C84: prop_o65 | D84: 0.6744933 | E84: -0.23910582 | F84: 1.5880924 | G84: 1245.6421 | H84: 1343.1263 | I84: First | J84: Simple | K84: Random | L84: =TEXT(ROUND(D84,2),"0.00") & "[" & TEXT(ROUND(E84,2),"0.00") & "," & TEXT(ROUND(F84,2),"0.00") & "]" -> 0.67[-0.24,1.59]
...

Sheet first_dose_table
A1: First
C2: Simple | F2: Lasso | I2: Stepwise
A3: Variable | B3: Variable | C3: Fixed | D3: Random | F3: Fixed | G3: Random | I3: Fixed | J3: Random
A4: Pop_per_km2 | B4: Population per km2 | C4: {=_xlfn.XLOOKUP($A4&C$3&$C$2&$A$1,doses_results!$C$2:$C$400&doses_results!$K$2:$K$400&doses_results!$J$2:$J$400&doses_results!$I$2:$I$400,doses_results!$L$2:$L$400,"",0)} -> -0.05[-0.51,0.41] | D4: {=_xlfn.XLOOKUP($A4&D$3&$C$2&$A$1,doses_results!$C$2:$C$400&doses_results!$K$2:$K$400&doses_results!$J$2:$J$400&doses_results!$I$2:$I$400,doses_results!$L$2:$L$400,"",0)} -> -0.10[-0.56,0.36] | E4: {=_xlfn.XLOOKUP($A4&E$3&$C$2&$A$1,doses_results!$C$2:$C$400&doses_results!$K$2:$K$400&doses_results!$J$2:$J$400&doses_results!$I$2:$I$400,doses_results!$L$2:$L$400,"",0)} | F4: {=_xlfn.XLOOKUP($A4&F$3&$F$2&$A$1,doses_results!$C$2:$C$400&doses_results!$K$2:$K$400&doses_results!$J$2:$J$400&doses_results!$I$2:$I$400,doses_results!$L$2:$L$400,"",0)} -> -10.05[-23.88,3.78] | G4: {=_xlfn.XLOOKUP($A4&G$3&$F$2&$A$1,doses_results!$C$2:$C$400&doses_results!$K$2:$K$400&doses_results!$J$2:$J$400&doses_results!$I$2:$I$400,doses_results!$L$2:$L$400,"",0)} -> -9.06[-22.82,4.70] | H4: {=_xlfn.XLOOKUP($A4&H$3&$C$2&$A$1,doses_results!$C$2:$C$400&doses_results!$K$2:$K$400&doses_results!$J$2:$J$400&doses_results!$I$2:$I$400,doses_results!$L$2:$L$400,"",0)} | I4: {=_xlfn.XLOOKUP($A4&I$3&$I$2&$A$1,doses_results!$C$2:$C$400&doses_results!$K$2:$K$400&doses_results!$J$2:$J$400&doses_results!$I$2:$I$400,doses_results!$L$2:$L$400,"",0)} -> -7.02[-20.46,6.41] | J4: {=_xlfn.XLOOKUP($A4&J$3&$I$2&$A$1,doses_results!$C$2:$C$400&doses_results!$K$2:$K$400&doses_results!$J$2:$J$400&doses_results!$I$2:$I$400,doses_results!$L$2:$L$400,"",0)}
A5: prop_travelling_to_work | B5: Proportion Travelling To Work | C5: {=_xlfn.XLOOKUP($A5&C$3&$C$2&$A$1,doses_results!$C$2:$C$400&doses_results!$K$2:$K$400&doses_results!$J$2:$J$400&doses_results!$I$2:$I$400,doses_results!$L$2:$L$400,"",0)} -> -0.10[-1.14,0.93] | D5: {=_xlfn.XLOOKUP($A5&D$3&$C$2&$A$1,doses_results!$C$2:$C$400&doses_results!$K$2:$K$400&doses_results!$J$2:$J$400&doses_results!$I$2:$I$400,doses_results!$L$2:$L$400,"",0)} -> 0.04[-1.00,1.07] | E5: {=_xlfn.XLOOKUP($A5&E$3&$C$2&$A$1,doses_results!$C$2:$C$400&doses_results!$K$2:$K$400&doses_results!$J$2:$J$400&doses_results!$I$2:$I$400,doses_results!$L$2:$L$400,"",0)} | F5: {=_xlfn.XLOOKUP($A5&F$3&$F$2&$A$1,doses_results!$C$2:$C$400&doses_results!$K$2:$K$400&doses_results!$J$2:$J$400&doses_results!$I$2:$I$400,doses_results!$L$2:$L$400,"",0)} | G5: {=_xlfn.XLOOKUP($A5&G$3&$F$2&$A$1,doses_results!$C$2:$C$400&doses_results!$K$2:$K$400&doses_results!$J$2:$J$400&doses_results!$I$2:$I$400,doses_results!$L$2:$L$400,"",0)} | H5: {=_xlfn.XLOOKUP($A5&H$3&$C$2&$A$1,doses_results!$C$2:$C$400&doses_results!$K$2:$K$400&doses_results!$J$2:$J$400&doses_results!$I$2:$I$400,doses_results!$L$2:$L$400,"",0)} | I5: {=_xlfn.XLOOKUP($A5&I$3&$I$2&$A$1,doses_results!$C$2:$C$400&doses_results!$K$2:$K$400&doses_results!$J$2:$J$400&doses_results!$I$2:$I$400,doses_results!$L$2:$L$400,"",0)} | J5: {=_xlfn.XLOOKUP($A5&J$3&$I$2&$A$1,doses_results!$C$2:$C$400&doses_results!$K$2:$K$400&doses_results!$J$2:$J$400&doses_results!$I$2:$I$400,doses_results!$L$2:$L$400,"",0)} -> 0.55[0.25,0.84]
A6: prop_not_in_work | B6: Proportion Not In Work | C6: {=_xlfn.XLOOKUP($A6&C$3&$C$2&$A$1,doses_results!$C$2:$C$400&doses_results!$K$2:$K$400&doses_results!$J$2:$J$400&doses_results!$I$2:$I$400,doses_results!$L$2:$L$400,"",0)} -> -0.88[-2.15,0.39] | D6: {=_xlfn.XLOOKUP($A6&D$3&$C$2&$A$1,doses_results!$C$2:$C$400&doses_results!$K$2:$K$400&doses_results!$J$2:$J$400&doses_results!$I$2:$I$400,doses_results!$L$2:$L$400,"",0)} -> -0.75[-2.04,0.54] | E6: {=_xlfn.XLOOKUP($A6&E$3&$C$2&$A$1,doses_results!$C$2:$C$400&doses_results!$K$2:$K$400&doses_results!$J$2:$J$400&doses_results!$I$2:$I$400,doses_results!$L$2:$L$400,"",0)} | F6: {=_xlfn.XLOOKUP($A6&F$3&$F$2&$A$1,doses_results!$C$2:$C$400&doses_results!$K$2:$K$400&doses_results!$J$2:$J$400&doses_results!$I$2:$I$400,doses_results!$L$2:$L$400,"",0)} -> -0.24[-0.77,0.29] | G6: {=_xlfn.XLOOKUP($A6&G$3&$F$2&$A$1,doses_results!$C$2:$C$400&doses_results!$K$2:$K$400&doses_results!$J$2:$J$400&doses_results!$I$2:$I$400,doses_results!$L$2:$L$400,"",0)} -> -0.24[-0.78,0.30] | H6: {=_xlfn.XLOOKUP($A6&H$3&$C$2&$A$1,doses_results!$C$2:$C$400&doses_results!$K$2:$K$400&doses_results!$J$2:$J$400&doses_results!$I$2:$I$400,doses_results!$L$2:$L$400,"",0)} | I6: {=_xlfn.XLOOKUP($A6&I$3&$I$2&$A$1,doses_results!$C$2:$C$400&doses_results!$K$2:$K$400&doses_results!$J$2:$J$400&doses_results!$I$2:$I$400,doses_results!$L$2:$L$400,"",0)} | J6: {=_xlfn.XLOOKUP($A6&J$3&$I$2&$A$1,doses_results!$C$2:$C$400&doses_results!$K$2:$K$400&doses_results!$J$2:$J$400&doses_results!$I$2:$I$400,doses_results!$L$2:$L$400,"",0)}
A7: prop_all_other_white | B7: Proportion All Other White | C7: {=_xlfn.XLOOKUP($A7&C$3&$C$2&$A$1,doses_results!$C$2:$C$400&doses_results!$K$2:$K$400&doses_results!$J$2:$J$400&doses_results!$I$2:$I$400,doses_results!$L$2:$L$400,"",0)} -> -2.63[-2.97,-2.28] | D7: {=_xlfn.XLOOKUP($A7&D$3&$C$2&$A$1,doses_results!$C$2:$C$400&doses_results!$K$2:$K$400&doses_results!$J$2:$J$400&doses_results!$I$2:$I$400,doses_results!$L$2:$L$400,"",0)} -> -2.62[-2.97,-2.27] | E7: {=_xlfn.XLOOKUP($A7&E$3&$C$2&$A$1,doses_results!$C$2:$C$400&doses_results!$K$2:$K$400&doses_results!$J$2:$J$400&doses_results!$I$2:$I$400,doses_results!$L$2:$L$400,"",0)} | F7: {=_xlfn.XLOOKUP($A7&F$3&$F$2&$A$1,doses_results!$C$2:$C$400&doses_results!$K$2:$K$400&doses_results!$J$2:$J$400&doses_results!$I$2:$I$400,doses_results!$L$2:$L$400,"",0)} -> -2.85[-3.15,-2.55] | G7: {=_xlfn.XLOOKUP($A7&G$3&$F$2&$A$1,doses_results!$C$2:$C$400&doses_results!$K$2:$K$400&doses_results!$J$2:$J$400&doses_results!$I$2:$I$400,doses_results!$L$2:$L$400,"",0)} -> -2.82[-3.12,-2.51] | H7: {=_xlfn.XLOOKUP($A7&H$3&$C$2&$A$1,doses_results!$C$2:$C$400&doses_results!$K$2:$K$400&doses_results!$J$2:$J$400&doses_results!$I$2:$I$400,doses_results!$L$2:$L$400,"",0)} | I7: {=_xlfn.XLOOKUP($A7&I$3&$I$2&$A$1,doses_results!$C$2:$C$400&doses_results!$K$2:$K$400&doses_results!$J$2:$J$400&doses_results!$I$2:$I$400,doses_results!$L$2:$L$400,"",0)} -> -2.82[-3.11,-2.52] | J7: {=_xlfn.XLOOKUP($A7&J$3&$I$2&$A$1,doses_results!$C$2:$C$400&doses_results!$K$2:$K$400&doses_results!$J$2:$J$400&doses_results!$I$2:$I$400,doses_results!$L$2:$L$400,"",0)} -> -2.58[-2.89,-2.26]
A8: prop_mixed_multiple | B8: Proportion Mixed | C8: {=_xlfn.XLOOKUP($A8&C$3&$C$2&$A$1,doses_results!$C$2:$C$400&doses_results!$K$2:$K$400&doses_results!$J$2:$J$400&doses_results!$I$2:$I$400,doses_results!$L$2:$L$400,"",0)} -> -0.26[-0.56,0.04] | D8: {=_xlfn.XLOOKUP($A8&D$3&$C$2&$A$1,doses_results!$C$2:$C$400&doses_results!$K$2:$K$400&doses_results!$J$2:$J$400&doses_results!$I$2:$I$400,doses_results!$L$2:$L$400,"",0)} -> -0.25[-0.55,0.05] | E8: {=_xlfn.XLOOKUP($A8&E$3&$C$2&$A$1,doses_results!$C$2:$C$400&doses_results!$K$2:$K$400&doses_results!$J$2:$J$400&doses_results!$I$2:$I$400,doses_results!$L$2:$L$400,"",0)} | F8: {=_xlfn.XLOOKUP($A8&F$3&$F$2&$A$1,doses_results!$C$2:$C$400&doses_results!$K$2:$K$400&doses_results!$J$2:$J$400&doses_results!$I$2:$I$400,doses_results!$L$2:$L$400,"",0)} | G8: {=_xlfn.XLOOKUP($A8&G$3&$F$2&$A$1,doses_results!$C$2:$C$400&doses_results!$K$2:$K$400&doses_results!$J$2:$J$400&doses_results!$I$2:$I$400,doses_results!$L$2:$L$400,"",0)} | H8: {=_xlfn.XLOOKUP($A8&H$3&$C$2&$A$1,doses_results!$C$2:$C$400&doses_results!$K$2:$K$400&doses_results!$J$2:$J$400&doses_results!$I$2:$I$400,doses_results!$L$2:$L$400,"",0)} | I8: {=_xlfn.XLOOKUP($A8&I$3&$I$2&$A$1,doses_results!$C$2:$C$400&doses_results!$K$2:$K$400&doses_results!$J$2:$J$400&doses_results!$I$2:$I$400,doses_results!$L$2:$L$400,"",0)} | J8: {=_xlfn.XLOOKUP($A8&J$3&$I$2&$A$1,doses_results!$C$2:$C$400&doses_results!$K$2:$K$400&doses_results!$J$2:$J$400&doses_results!$I$2:$I$400,doses_results!$L$2:$L$400,"",0)}
A9: prop_asian | B9: Proportion Asian | C9: {=_xlfn.XLOOKUP($A9&C$3&$C$2&$A$1,doses_results!$C$2:$C$400&doses_results!$K$2:$K$400&doses_results!$J$2:$J$400&doses_results!$I$2:$I$400,doses_results!$L$2:$L$400,"",0)} -> -0.46[-0.75,-0.17] | D9: {=_xlfn.XLOOKUP($A9&D$3&$C$2&$A$1,doses_results!$C$2:$C$400&doses_results!$K$2:$K$400&doses_results!$J$2:$J$400&doses_results!$I$2:$I$400,doses_results!$L$2:$L$400,"",0)} -> -0.45[-0.74,-0.16] | E9: {=_xlfn.XLOOKUP($A9&E$3&$C$2&$A$1,doses_results!$C$2:$C$400&doses_results!$K$2:$K$400&doses_results!$J$2:$J$400&doses_results!$I$2:$I$400,doses_results!$L$2:$L$400,"",0)} | F9: {=_xlfn.XLOOKUP($A9&F$3&$F$2&$A$1,doses_results!$C$2:$C$400&doses_results!$K$2:$K$400&doses_results!$J$2:$J$400&doses_results!$I$2:$I$400,doses_results!$L$2:$L$400,"",0)} -> -0.73[-1.00,-0.46] | G9: {=_xlfn.XLOOKUP($A9&G$3&$F$2&$A$1,doses_results!$C$2:$C$400&doses_results!$K$2:$K$400&doses_results!$J$2:$J$400&doses_results!$I$2:$I$400,doses_results!$L$2:$L$400,"",0)} -> -0.72[-0.99,-0.45] | H9: {=_xlfn.XLOOKUP($A9&H$3&$C$2&$A$1,doses_results!$C$2:$C$400&doses_results!$K$2:$K$400&doses_results!$J$2:$J$400&doses_results!$I$2:$I$400,doses_results!$L$2:$L$400,"",0)} | I9: {=_xlfn.XLOOKUP($A9&I$3&$I$2&$A$1,doses_results!$C$2:$C$400&doses_results!$K$2:$K$400&doses_results!$J$2:$J$400&doses_results!$I$2:$I$400,doses_results!$L$2:$L$400,"",0)} -> -0.66[-0.92,-0.41] | J9: {=_xlfn.XLOOKUP($A9&J$3&$I$2&$A$1,doses_results!$C$2:$C$400&doses_results!$K$2:$K$400&doses_results!$J$2:$J$400&doses_results!$I$2:$I$400,doses_results!$L$2:$L$400,"",0)} -> -0.65[-0.89,-0.40]
A10: prop_black_afr_car | B10: Proportion Black / African / Caribbean | C10: {=_xlfn.XLOOKUP($A10&C$3&$C$2&$A$1,doses_results!$C$2:$C$400&doses_results!$K$2:$K$400&doses_results!$J$2:$J$400&doses_results!$I$2:$I$400,doses_results!$L$2:$L$400,"",0)} -> -0.80[-1.23,-0.38] | D10: {=_xlfn.XLOOKUP($A10&D$3&$C$2&$A$1,doses_results!$C$2:$C$400&doses_results!$K$2:$K$400&doses_results!$J$2:$J$400&doses_results!$I$2:$I$400,doses_results!$L$2:$L$400,"",0)} -> -0.81[-1.24,-0.39] | E10: {=_xlfn.XLOOKUP($A10&E$3&$C$2&$A$1,doses_results!$C$2:$C$400&doses_results!$K$2:$K$400&doses_results!$J$2:$J$400&doses_results!$I$2:$I$400,doses_results!$L$2:$L$400,"",0)} | F10: {=_xlfn.XLOOKUP($A10&F$3&$F$2&$A$1,doses_results!$C$2:$C$400&doses_results!$K$2:$K$400&doses_results!$J$2:$J$400&doses_results!$I$2:$I$400,doses_results!$L$2:$L$400,"",0)} -> -1.33[-1.67,-0.99] | G10: {=_xlfn.XLOOKUP($A10&G$3&$F$2&$A$1,doses_results!$C$2:$C$400&doses_results!$K$2:$K$400&doses_results!$J$2:$J$400&doses_results!$I$2:$I$400,doses_results!$L$2:$L$400,"",0)} -> -1.30[-1.64,-0.95] | H10: {=_xlfn.XLOOKUP($A10&H$3&$C$2&$A$1,doses_results!$C$2:$C$400&doses_results!$K$2:$K$400&doses_results!$J$2:$J$400&doses_results!$I$2:$I$400,doses_results!$L$2:$L$400,"",0)} | I10: {=_xlfn.XLOOKUP($A10&I$3&$I$2&$A$1,doses_results!$C$2:$C$400&doses_results!$K$2:$K$400&doses_results!$J$2:$J$400&doses_results!$I$2:$I$400,doses_results!$L$2:$L$400,"",0)} -> -1.33[-1.68,-0.99] | J10: {=_xlfn.XLOOKUP($A10&J$3&$I$2&$A$1,doses_results!$C$2:$C$400&doses_results!$K$2:$K$400&doses_results!$J$2:$J$400&doses_results!$I$2:$I$400,doses_results!$L$2:$L$400,"",0)} -> -1.12[-1.44,-0.81]
A11: prop_other | B11: Proportion Other Ethnicity | C11: {=_xlfn.XLOOKUP($A11&C$3&$C$2&$A$1,doses_results!$C$2:$C$400&doses_results!$K$2:$K$400&doses_results!$J$2:$J$400&doses_results!$I$2:$I$400,doses_results!$L$2:$L$400,"",0)} -> -0.01[-0.41,0.39] | D11: {=_xlfn.XLOOKUP($A11&D$3&$C$2&$A$1,doses_results!$C$2:$C$400&doses_results!$K$2:$K$400&doses_results!$J$2:$J$400&doses_results!$I$2:$I$400,doses_results!$L$2:$L$400,"",0)} -> -0.03[-0.43,0.38] | E11: {=_xlfn.XLOOKUP($A11&E$3&$C$2&$A$1,doses_results!$C$2:$C$400&doses_results!$K$2:$K$400&doses_results!$J$2:$J$400&doses_results!$I$2:$I$400,doses_results!$L$2:$L$400,"",0)} | F11: {=_xlfn.XLOOKUP($A11&F$3&$F$2&$A$1,doses_results!$C$2:$C$400&doses_results!$K$2:$K$400&doses_results!$J$2:$J$400&doses_results!$I$2:$I$400,doses_results!$L$2:$L$400,"",0)} | G11: {=_xlfn.XLOOKUP($A11&G$3&$F$2&$A$1,doses_results!$C$2:$C$400&doses_results!$K$2:$K$400&doses_results!$J$2:$J$400&doses_results!$I$2:$I$400,doses_results!$L$2:$L$400,"",0)} | H11: {=_xlfn.XLOOKUP($A11&H$3&$C$2&$A$1,doses_results!$C$2:$C$400&doses_results!$K$2:$K$400&doses_results!$J$2:$J$400&doses_results!$I$2:$I$400,doses_results!$L$2:$L$400,"",0)} | I11: {=_xlfn.XLOOKUP($A11&I$3&$I$2&$A$1,doses_results!$C$2:$C$400&doses_results!$K$2:$K$400&doses_results!$J$2:$J$400&doses_results!$I$2:$I$400,doses_results!$L$2:$L$400,"",0)} | J11: {=_xlfn.XLOOKUP($A11&J$3&$I$2&$A$1,doses_results!$C$2:$C$400&doses_results!$K$2:$K$400&doses_results!$J$2:$J$400&doses_results!$I$2:$I$400,doses_results!$L$2:$L$400,"",0)}
A12: IMD_Average_score | B12: IMD Average Score | C12: {=_xlfn.XLOOKUP($A12&C$3&$C$2&$A$1,doses_results!$C$2:$C$400&doses_results!$K$2:$K$400&doses_results!$J$2:$J$400&doses_results!$I$2:$I$400,doses_results!$L$2:$L$400,"",0)} -> 0.25[-1.19,1.69] | D12: {=_xlfn.XLOOKUP($A12&D$3&$C$2&$A$1,doses_results!$C$2:$C$400&doses_results!$K$2:$K$400&doses_results!$J$2:$J$400&doses_results!$I$2:$I$400,doses_results!$L$2:$L$400,"",0)} -> 0.26[-1.18,1.70] | E12: {=_xlfn.XLOOKUP($A12&E$3&$C$2&$A$1,doses_results!$C$2:$C$400&doses_results!$K$2:$K$400&doses_results!$J$2:$J$400&doses_results!$I$2:$I$400,doses_results!$L$2:$L$400,"",0)} | F12: {=_xlfn.XLOOKUP($A12&F$3&$F$2&$A$1,doses_results!$C$2:$C$400&doses_results!$K$2:$K$400&doses_results!$J$2:$J$400&doses_results!$I$2:$I$400,doses_results!$L$2:$L$400,"",0)} -> -0.11[-1.15,0.93] | G12: {=_xlfn.XLOOKUP($A12&G$3&$F$2&$A$1,doses_results!$C$2:$C$400&doses_results!$K$2:$K$400&doses_results!$J$2:$J$400&doses_results!$I$2:$I$400,doses_results!$L$2:$L$400,"",0)} -> -0.05[-1.09,0.99] | H12: {=_xlfn.XLOOKUP($A12&H$3&$C$2&$A$1,doses_results!$C$2:$C$400&doses_results!$K$2:$K$400&doses_results!$J$2:$J$400&doses_results!$I$2:$I$400,doses_results!$L$2:$L$400,"",0)} | I12: {=_xlfn.XLOOKUP($A12&I$3&$I$2&$A$1,doses_results!$C$2:$C$400&doses_results!$K$2:$K$400&doses_results!$J$2:$J$400&doses_results!$I$2:$I$400,doses_results!$L$2:$L$400,"",0)} | J12: {=_xlfn.XLOOKUP($A12&J$3&$I$2&$A$1,doses_results!$C$2:$C$400&doses_results!$K$2:$K$400&doses_results!$J$2:$J$400&doses_results!$I$2:$I$400,doses_results!$L$2:$L$400,"",0)}
A13: prop_o65 | B13: Proportion Over 65 | C13: {=_xlfn.XLOOKUP($A13&C$3&$C$2&$A$1,doses_results!$C$2:$C$400&doses_results!$K$2:$K$400&doses_results!$J$2:$J$400&doses_results!$I$2:$I$400,doses_results!$L$2:$L$400,"",0)} -> 0.63[-0.27,1.53] | D13: {=_xlfn.XLOOKUP($A13&D$3&$C$2&$A$1,doses_results!$C$2:$C$400&doses_results!$K$2:$K$400&doses_results!$J$2:$J$400&doses_results!$I$2:$I$400,doses_results!$L$2:$L$400,"",0)} -> 0.67[-0.24,1.59] | E13: {=_xlfn.XLOOKUP($A13&E$3&$C$2&$A$1,doses_results!$C$2:$C$400&doses_results!$K$2:$K$400&doses_results!$J$2:$J$400&doses_results!$I$2:$I$400,doses_results!$L$2:$L$400,"",0)} | F13: {=_xlfn.XLOOKUP($A13&F$3&$F$2&$A$1,doses_results!$C$2:$C$400&doses_results!$K$2:$K$400&doses_results!$J$2:$J$400&doses_results!$I$2:$I$400,doses_results!$L$2:$L$400,"",0)} -> -1.13[-2.22,-0.04] | G13: {=_xlfn.XLOOKUP($A13&G$3&$F$2&$A$1,doses_results!$C$2:$C$400&doses_results!$K$2:$K$400&doses_results!$J$2:$J$400&doses_results!$I$2:$I$400,doses_results!$L$2:$L$400,"",0)} -> -1.12[-2.22,-0.02] | H13: {=_xlfn.XLOOKUP($A13&H$3&$C$2&$A$1,doses_results!$C$2:$C$400&doses_results!$K$2:$K$400&doses_results!$J$2:$J$400&doses_results!$I$2:$I$400,doses_results!$L$2:$L$400,"",0)} | I13: {=_xlfn.XLOOKUP($A13&I$3&$I$2&$A$1,doses_results!$C$2:$C$400&doses_results!$K$2:$K$400&doses_results!$J$2:$J$400&doses_results!$I$2:$I$400,doses_results!$L$2:$L$400,"",0)} -> -1.50[-2.28,-0.72] | J13: {=_xlfn.XLOOKUP($A13&J$3&$I$2&$A$1,doses_results!$C$2:$C$400&doses_results!$K$2:$K$400&doses_results!$J$2:$J$400&doses_results!$I$2:$I$400,doses_results!$L$2:$L$400,"",0)}
A14: prop_u25 | B14: Proportion Under 25 | C14: {=_xlfn.XLOOKUP($A14&C$3&$C$2&$A$1,doses_results!$C$2:$C$400&doses_results!$K$2:$K$400&doses_results!$J$2:$J$400&doses_results!$I$2:$I$400,doses_results!$L$2:$L$400,"",0)} -> -1.29[-1.93,-0.65] | D14: {=_xlfn.XLOOKUP($A14&D$3&$C$2&$A$1,doses_results!$C$2:$C$400&doses_results!$K$2:$K$400&doses_results!$J$2:$J$400&doses_results!$I$2:$I$400,doses_results!$L$2:$L$400,"",0)} -> -1.27[-1.93,-0.60] | E14: {=_xlfn.XLOOKUP($A14&E$3&$C$2&$A$1,doses_results!$C$2:$C$400&doses_results!$K$2:$K$400&doses_results!$J$2:$J$400&doses_results!$I$2:$I$400,doses_results!$L$2:$L$400,"",0)} | F14: {=_xlfn.XLOOKUP($A14&F$3&$F$2&$A$1,doses_results!$C$2:$C$400&doses_results!$K$2:$K$400&doses_results!$J$2:$J$400&doses_results!$I$2:$I$400,doses_results!$L$2:$L$400,"",0)} -> -0.30[-1.10,0.51] | G14: {=_xlfn.XLOOKUP($A14&G$3&$F$2&$A$1,doses_results!$C$2:$C$400&doses_results!$K$2:$K$400&doses_results!$J$2:$J$400&doses_results!$I$2:$I$400,doses_results!$L$2:$L$400,"",0)} -> -0.36[-1.20,0.47] | H14: {=_xlfn.XLOOKUP($A14&H$3&$C$2&$A$1,doses_results!$C$2:$C$400&doses_results!$K$2:$K$400&doses_results!$J$2:$J$400&doses_results!$I$2:$I$400,doses_results!$L$2:$L$400,"",0)} | I14: {=_xlfn.XLOOKUP($A14&I$3&$I$2&$A$1,doses_results!$C$2:$C$400&doses_results!$K$2:$K$400&doses_results!$J$2:$J$400&doses_results!$I$2:$I$400,doses_results!$L$2:$L$400,"",0)} | J14: {=_xlfn.XLOOKUP($A14&J$3&$I$2&$A$1,doses_results!$C$2:$C$400&doses_results!$K$2:$K$400&doses_results!$J$2:$J$400&doses_results!$I$2:$I$400,doses_results!$L$2:$L$400,"",0)}
A15: Median_annual_income | B15: Median Annual Income | C15: {=_xlfn.XLOOKUP($A15&C$3&$C$2&$A$1,doses_results!$C$2:$C$400&doses_results!$K$2:$K$400&doses_results!$J$2:$J$400&doses_results!$I$2:$I$400,doses_results!$L$2:$L$400,"",0)} -> -0.28[-0.60,0.05] | D15: {=_xlfn.XLOOKUP($A15&D$3&$C$2&$A$1,doses_results!$C$2:$C$400&doses_results!$K$2:$K$400&doses_results!$J$2:$J$400&doses_results!$I$2:$I$400,doses_results!$L$2:$L$400,"",0)} -> -0.26[-0.59,0.07] | E15: {=_xlfn.XLOOKUP($A15&E$3&$C$2&$A$1,doses_results!$C$2:$C$400&doses_results!$K$2:$K$400&doses_results!$J$2:$J$400&doses_results!$I$2:$I$400,doses_results!$L$2:$L$400,"",0)} | F15: {=_xlfn.XLOOKUP($A15&F$3&$F$2&$A$1,doses_results!$C$2:$C$400&doses_results!$K$2:$K$400&doses_results!$J$2:$J$400&doses_results!$I$2:$I$400,doses_results!$L$2:$L$400,"",0)} | G15: {=_xlfn.XLOOKUP($A15&G$3&$F$2&$A$1,doses_results!$C$2:$C$400&doses_results!$K$2:$K$400&doses_results!$J$2:$J$400&doses_results!$I$2:$I$400,doses_results!$L$2:$L$400,"",0)} | H15: {=_xlfn.XLOOKUP($A15&H$3&$C$2&$A$1,doses_results!$C$2:$C$400&doses_results!$K$2:$K$400&doses_results!$J$2:$J$400&doses_results!$I$2:$I$400,doses_results!$L$2:$L$400,"",0)} | I15: {=_xlfn.XLOOKUP($A15&I$3&$I$2&$A$1,doses_results!$C$2:$C$400&doses_results!$K$2:$K$400&doses_results!$J$2:$J$400&doses_results!$I$2:$I$400,doses_results!$L$2:$L$400,"",0)} | J15: {=_xlfn.XLOOKUP($A15&J$3&$I$2&$A$1,doses_results!$C$2:$C$400&doses_results!$K$2:$K$400&doses_results!$J$2:$J$400&doses_results!$I$2:$I$400,doses_results!$L$2:$L$400,"",0)}
... A35: ASC_rapid_testing | B35: ASC Rapid Testing | C35: {=_xlfn.XLOOKUP($A35&C$3&$C$2&$A$1,doses_results!$C$2:$C$400&doses_results!$K$2:$K$400&doses_results!$J$2:$J$400&doses_results!$I$2:$I$400,doses_results!$L$2:$L$400,"",0)} | D35: {=_xlfn.XLOOKUP($A35&D$3&$C$2&$A$1,doses_results!$C$2:$C$400&doses_results!$K$2:$K$400&doses_results!$J$2:$J$400&doses_results!$I$2:$I$400,doses_results!$L$2:$L$400,"",0)} | E35: {=_xlfn.XLOOKUP($A35&E$3&$C$2&$A$1,doses_results!$C$2:$C$400&doses_results!$K$2:$K$400&doses_results!$J$2:$J$400&doses_results!$I$2:$I$400,doses_results!$L$2:$L$400,"",0)} | F35: {=_xlfn.XLOOKUP($A35&F$3&$F$2&$A$1,doses_results!$C$2:$C$400&doses_results!$K$2:$K$400&doses_results!$J$2:$J$400&doses_results!$I$2:$I$400,doses_results!$L$2:$L$400,"",0)} | G35: {=_xlfn.XLOOKUP($A35&G$3&$F$2&$A$1,doses_results!$C$2:$C$400&doses_results!$K$2:$K$400&doses_results!$J$2:$J$400&doses_results!$I$2:$I$400,doses_results!$L$2:$L$400,"",0)} | H35: {=_xlfn.XLOOKUP($A35&H$3&$C$2&$A$1,doses_results!$C$2:$C$400&doses_results!$K$2:$K$400&doses_results!$J$2:$J$400&doses_results!$I$2:$I$400,doses_results!$L$2:$L$400,"",0)} | I35: {=_xlfn.XLOOKUP($A35&I$3&$I$2&$A$1,doses_results!$C$2:$C$400&doses_results!$K$2:$K$400&doses_results!$J$2:$J$400&doses_results!$I$2:$I$400,doses_results!$L$2:$L$400,"",0)} | J35: {=_xlfn.XLOOKUP($A35&J$3&$I$2&$A$1,doses_results!$C$2:$C$400&doses_results!$K$2:$K$400&doses_results!$J$2:$J$400&doses_results!$I$2:$I$400,doses_results!$L$2:$L$400,"",0)} -> 0.78[-0.39,1.95]

Sheet second_dose_table
A1: Second
C2: Simple | F2: Lasso | I2: Stepwise
A3: Variable | B3: Variable | C3: Fixed | D3: Random | F3: Fixed | G3: Random | I3: Fixed | J3: Random
A4: Pop_per_km2 | B4: Population per km2 | C4: {=_xlfn.XLOOKUP($A4&C$3&$C$2&$A$1,doses_results!$C$2:$C$400&doses_results!$K$2:$K$400&doses_results!$J$2:$J$400&doses_results!$I$2:$I$400,doses_results!$L$2:$L$400,"",0)} -> -0.17[-0.64,0.30] | D4: {=_xlfn.XLOOKUP($A4&D$3&$C$2&$A$1,doses_results!$C$2:$C$400&doses_results!$K$2:$K$400&doses_results!$J$2:$J$400&doses_results!$I$2:$I$400,doses_results!$L$2:$L$400,"",0)} -> -0.22[-0.69,0.25] | E4: {=_xlfn.XLOOKUP($A4&E$3&$C$2&$A$1,doses_results!$C$2:$C$400&doses_results!$K$2:$K$400&doses_results!$J$2:$J$400&doses_results!$I$2:$I$400,doses_results!$L$2:$L$400,"",0)} | F4: {=_xlfn.XLOOKUP($A4&F$3&$F$2&$A$1,doses_results!$C$2:$C$400&doses_results!$K$2:$K$400&doses_results!$J$2:$J$400&doses_results!$I$2:$I$400,doses_results!$L$2:$L$400,"",0)} -> -15.56[-29.58,-1.54] | G4: {=_xlfn.XLOOKUP($A4&G$3&$F$2&$A$1,doses_results!$C$2:$C$400&doses_results!$K$2:$K$400&doses_results!$J$2:$J$400&doses_results!$I$2:$I$400,doses_results!$L$2:$L$400,"",0)} -> -14.94[-28.93,-0.94] | H4: {=_xlfn.XLOOKUP($A4&H$3&$C$2&$A$1,doses_results!$C$2:$C$400&doses_results!$K$2:$K$400&doses_results!$J$2:$J$400&doses_results!$I$2:$I$400,doses_results!$L$2:$L$400,"",0)} | I4: {=_xlfn.XLOOKUP($A4&I$3&$I$2&$A$1,doses_results!$C$2:$C$400&doses_results!$K$2:$K$400&doses_results!$J$2:$J$400&doses_results!$I$2:$I$400,doses_results!$L$2:$L$400,"",0)} -> -12.65[-26.21,0.92] | J4: {=_xlfn.XLOOKUP($A4&J$3&$I$2&$A$1,doses_results!$C$2:$C$400&doses_results!$K$2:$K$400&doses_results!$J$2:$J$400&doses_results!$I$2:$I$400,doses_results!$L$2:$L$400,"",0)}
A5: prop_travelling_to_work | B5: Proportion Travelling To Work | C5: {=_xlfn.XLOOKUP($A5&C$3&$C$2&$A$1,doses_results!$C$2:$C$400&doses_results!$K$2:$K$400&doses_results!$J$2:$J$400&doses_results!$I$2:$I$400,doses_results!$L$2:$L$400,"",0)} -> -0.01[-1.07,1.04] | D5: {=_xlfn.XLOOKUP($A5&D$3&$C$2&$A$1,doses_results!$C$2:$C$400&doses_results!$K$2:$K$400&doses_results!$J$2:$J$400&doses_results!$I$2:$I$400,doses_results!$L$2:$L$400,"",0)} -> 0.10[-0.96,1.16] | E5: {=_xlfn.XLOOKUP($A5&E$3&$C$2&$A$1,doses_results!$C$2:$C$400&doses_results!$K$2:$K$400&doses_results!$J$2:$J$400&doses_results!$I$2:$I$400,doses_results!$L$2:$L$400,"",0)} | F5: {=_xlfn.XLOOKUP($A5&F$3&$F$2&$A$1,doses_results!$C$2:$C$400&doses_results!$K$2:$K$400&doses_results!$J$2:$J$400&doses_results!$I$2:$I$400,doses_results!$L$2:$L$400,"",0)} | G5: {=_xlfn.XLOOKUP($A5&G$3&$F$2&$A$1,doses_results!$C$2:$C$400&doses_results!$K$2:$K$400&doses_results!$J$2:$J$400&doses_results!$I$2:$I$400,doses_results!$L$2:$L$400,"",0)} | H5: {=_xlfn.XLOOKUP($A5&H$3&$C$2&$A$1,doses_results!$C$2:$C$400&doses_results!$K$2:$K$400&doses_results!$J$2:$J$400&doses_results!$I$2:$I$400,doses_results!$L$2:$L$400,"",0)} | I5: {=_xlfn.XLOOKUP($A5&I$3&$I$2&$A$1,doses_results!$C$2:$C$400&doses_results!$K$2:$K$400&doses_results!$J$2:$J$400&doses_results!$I$2:$I$400,doses_results!$L$2:$L$400,"",0)} | J5: {=_xlfn.XLOOKUP($A5&J$3&$I$2&$A$1,doses_results!$C$2:$C$400&doses_results!$K$2:$K$400&doses_results!$J$2:$J$400&doses_results!$I$2:$I$400,doses_results!$L$2:$L$400,"",0)} -> 0.60[0.31,0.90]
A6: prop_not_in_work | B6: Proportion Not In Work | C6: {=_xlfn.XLOOKUP($A6&C$3&$C$2&$A$1,doses_results!$C$2:$C$400&doses_results!$K$2:$K$400&doses_results!$J$2:$J$400&doses_results!$I$2:$I$400,doses_results!$L$2:$L$400,"",0)} -> -0.84[-2.14,0.46] | D6: {=_xlfn.XLOOKUP($A6&D$3&$C$2&$A$1,doses_results!$C$2:$C$400&doses_results!$K$2:$K$400&doses_results!$J$2:$J$400&doses_results!$I$2:$I$400,doses_results!$L$2:$L$400,"",0)} -> -0.75[-2.06,0.57] | E6: {=_xlfn.XLOOKUP($A6&E$3&$C$2&$A$1,doses_results!$C$2:$C$400&doses_results!$K$2:$K$400&doses_results!$J$2:$J$400&doses_results!$I$2:$I$400,doses_results!$L$2:$L$400,"",0)} | F6: {=_xlfn.XLOOKUP($A6&F$3&$F$2&$A$1,doses_results!$C$2:$C$400&doses_results!$K$2:$K$400&doses_results!$J$2:$J$400&doses_results!$I$2:$I$400,doses_results!$L$2:$L$400,"",0)} -> -0.25[-0.78,0.29] | G6: {=_xlfn.XLOOKUP($A6&G$3&$F$2&$A$1,doses_results!$C$2:$C$400&doses_results!$K$2:$K$400&doses_results!$J$2:$J$400&doses_results!$I$2:$I$400,doses_results!$L$2:$L$400,"",0)} -> -0.26[-0.80,0.28] | H6: {=_xlfn.XLOOKUP($A6&H$3&$C$2&$A$1,doses_results!$C$2:$C$400&doses_results!$K$2:$K$400&doses_results!$J$2:$J$400&doses_results!$I$2:$I$400,doses_results!$L$2:$L$400,"",0)} | I6: {=_xlfn.XLOOKUP($A6&I$3&$I$2&$A$1,doses_results!$C$2:$C$400&doses_results!$K$2:$K$400&doses_results!$J$2:$J$400&doses_results!$I$2:$I$400,doses_results!$L$2:$L$400,"",0)} | J6: {=_xlfn.XLOOKUP($A6&J$3&$I$2&$A$1,doses_results!$C$2:$C$400&doses_results!$K$2:$K$400&doses_results!$J$2:$J$400&doses_results!$I$2:$I$400,doses_results!$L$2:$L$400,"",0)}
A7: prop_all_other_white | B7: Proportion All Other White | C7: {=_xlfn.XLOOKUP($A7&C$3&$C$2&$A$1,doses_results!$C$2:$C$400&doses_results!$K$2:$K$400&doses_results!$J$2:$J$400&doses_results!$I$2:$I$400,doses_results!$L$2:$L$400,"",0)} -> -2.65[-3.00,-2.29] | D7: {=_xlfn.XLOOKUP($A7&D$3&$C$2&$A$1,doses_results!$C$2:$C$400&doses_results!$K$2:$K$400&doses_results!$J$2:$J$400&doses_results!$I$2:$I$400,doses_results!$L$2:$L$400,"",0)} -> -2.65[-3.01,-2.29] | E7: {=_xlfn.XLOOKUP($A7&E$3&$C$2&$A$1,doses_results!$C$2:$C$400&doses_results!$K$2:$K$400&doses_results!$J$2:$J$400&doses_results!$I$2:$I$400,doses_results!$L$2:$L$400,"",0)} | F7: {=_xlfn.XLOOKUP($A7&F$3&$F$2&$A$1,doses_results!$C$2:$C$400&doses_results!$K$2:$K$400&doses_results!$J$2:$J$400&doses_results!$I$2:$I$400,doses_results!$L$2:$L$400,"",0)} -> -2.89[-3.20,-2.59] | G7: {=_xlfn.XLOOKUP($A7&G$3&$F$2&$A$1,doses_results!$C$2:$C$400&doses_results!$K$2:$K$400&doses_results!$J$2:$J$400&doses_results!$I$2:$I$400,doses_results!$L$2:$L$400,"",0)} -> -2.87[-3.18,-2.57] | H7: {=_xlfn.XLOOKUP($A7&H$3&$C$2&$A$1,doses_results!$C$2:$C$400&doses_results!$K$2:$K$400&doses_results!$J$2:$J$400&doses_results!$I$2:$I$400,doses_results!$L$2:$L$400,"",0)} | I7: {=_xlfn.XLOOKUP($A7&I$3&$I$2&$A$1,doses_results!$C$2:$C$400&doses_results!$K$2:$K$400&doses_results!$J$2:$J$400&doses_results!$I$2:$I$400,doses_results!$L$2:$L$400,"",0)} -> -2.85[-3.15,-2.55] | J7: {=_xlfn.XLOOKUP($A7&J$3&$I$2&$A$1,doses_results!$C$2:$C$400&doses_results!$K$2:$K$400&doses_results!$J$2:$J$400&doses_results!$I$2:$I$400,doses_results!$L$2:$L$400,"",0)} -> -2.57[-2.89,-2.26]
A8: prop_mixed_multiple | B8: Proportion Mixed | C8: {=_xlfn.XLOOKUP($A8&C$3&$C$2&$A$1,doses_results!$C$2:$C$400&doses_results!$K$2:$K$400&doses_results!$J$2:$J$400&doses_results!$I$2:$I$400,doses_results!$L$2:$L$400,"",0)} -> -0.26[-0.57,0.05] | D8: {=_xlfn.XLOOKUP($A8&D$3&$C$2&$A$1,doses_results!$C$2:$C$400&doses_results!$K$2:$K$400&doses_results!$J$2:$J$400&doses_results!$I$2:$I$400,doses_results!$L$2:$L$400,"",0)} -> -0.25[-0.56,0.06] | E8: {=_xlfn.XLOOKUP($A8&E$3&$C$2&$A$1,doses_results!$C$2:$C$400&doses_results!$K$2:$K$400&doses_results!$J$2:$J$400&doses_results!$I$2:$I$400,doses_results!$L$2:$L$400,"",0)} | F8: {=_xlfn.XLOOKUP($A8&F$3&$F$2&$A$1,doses_results!$C$2:$C$400&doses_results!$K$2:$K$400&doses_results!$J$2:$J$400&doses_results!$I$2:$I$400,doses_results!$L$2:$L$400,"",0)} | G8: {=_xlfn.XLOOKUP($A8&G$3&$F$2&$A$1,doses_results!$C$2:$C$400&doses_results!$K$2:$K$400&doses_results!$J$2:$J$400&doses_results!$I$2:$I$400,doses_results!$L$2:$L$400,"",0)} | H8: {=_xlfn.XLOOKUP($A8&H$3&$C$2&$A$1,doses_results!$C$2:$C$400&doses_results!$K$2:$K$400&doses_results!$J$2:$J$400&doses_results!$I$2:$I$400,doses_results!$L$2:$L$400,"",0)} | I8: {=_xlfn.XLOOKUP($A8&I$3&$I$2&$A$1,doses_results!$C$2:$C$400&doses_results!$K$2:$K$400&doses_results!$J$2:$J$400&doses_results!$I$2:$I$400,doses_results!$L$2:$L$400,"",0)} | J8: {=_xlfn.XLOOKUP($A8&J$3&$I$2&$A$1,doses_results!$C$2:$C$400&doses_results!$K$2:$K$400&doses_results!$J$2:$J$400&doses_results!$I$2:$I$400,doses_results!$L$2:$L$400,"",0)}
A9: prop_asian | B9: Proportion Asian | C9: {=_xlfn.XLOOKUP($A9&C$3&$C$2&$A$1,doses_results!$C$2:$C$400&doses_results!$K$2:$K$400&doses_results!$J$2:$J$400&doses_results!$I$2:$I$400,doses_results!$L$2:$L$400,"",0)} -> -0.56[-0.86,-0.26] | D9: {=_xlfn.XLOOKUP($A9&D$3&$C$2&$A$1,doses_results!$C$2:$C$400&doses_results!$K$2:$K$400&doses_results!$J$2:$J$400&doses_results!$I$2:$I$400,doses_results!$L$2:$L$400,"",0)} -> -0.55[-0.84,-0.25] | E9: {=_xlfn.XLOOKUP($A9&E$3&$C$2&$A$1,doses_results!$C$2:$C$400&doses_results!$K$2:$K$400&doses_results!$J$2:$J$400&doses_results!$I$2:$I$400,doses_results!$L$2:$L$400,"",0)} | F9: {=_xlfn.XLOOKUP($A9&F$3&$F$2&$A$1,doses_results!$C$2:$C$400&doses_results!$K$2:$K$400&doses_results!$J$2:$J$400&doses_results!$I$2:$I$400,doses_results!$L$2:$L$400,"",0)} -> -0.84[-1.11,-0.56] | G9: {=_xlfn.XLOOKUP($A9&G$3&$F$2&$A$1,doses_results!$C$2:$C$400&doses_results!$K$2:$K$400&doses_results!$J$2:$J$400&doses_results!$I$2:$I$400,doses_results!$L$2:$L$400,"",0)} -> -0.83[-1.10,-0.55] | H9: {=_xlfn.XLOOKUP($A9&H$3&$C$2&$A$1,doses_results!$C$2:$C$400&doses_results!$K$2:$K$400&doses_results!$J$2:$J$400&doses_results!$I$2:$I$400,doses_results!$L$2:$L$400,"",0)} | I9: {=_xlfn.XLOOKUP($A9&I$3&$I$2&$A$1,doses_results!$C$2:$C$400&doses_results!$K$2:$K$400&doses_results!$J$2:$J$400&doses_results!$I$2:$I$400,doses_results!$L$2:$L$400,"",0)} -> -0.79[-1.05,-0.53] | J9: {=_xlfn.XLOOKUP($A9&J$3&$I$2&$A$1,doses_results!$C$2:$C$400&doses_results!$K$2:$K$400&doses_results!$J$2:$J$400&doses_results!$I$2:$I$400,doses_results!$L$2:$L$400,"",0)} -> -0.76[-1.00,-0.51]
A10: prop_black_afr_car | B10: Proportion Black / African / Caribbean | C10: {=_xlfn.XLOOKUP($A10&C$3&$C$2&$A$1,doses_results!$C$2:$C$400&doses_results!$K$2:$K$400&doses_results!$J$2:$J$400&doses_results!$I$2:$I$400,doses_results!$L$2:$L$400,"",0)} -> -0.73[-1.16,-0.29] | D10: {=_xlfn.XLOOKUP($A10&D$3&$C$2&$A$1,doses_results!$C$2:$C$400&doses_results!$K$2:$K$400&doses_results!$J$2:$J$400&doses_results!$I$2:$I$400,doses_results!$L$2:$L$400,"",0)} -> -0.74[-1.17,-0.30] | E10: {=_xlfn.XLOOKUP($A10&E$3&$C$2&$A$1,doses_results!$C$2:$C$400&doses_results!$K$2:$K$400&doses_results!$J$2:$J$400&doses_results!$I$2:$I$400,doses_results!$L$2:$L$400,"",0)} | F10: {=_xlfn.XLOOKUP($A10&F$3&$F$2&$A$1,doses_results!$C$2:$C$400&doses_results!$K$2:$K$400&doses_results!$J$2:$J$400&doses_results!$I$2:$I$400,doses_results!$L$2:$L$400,"",0)} -> -1.31[-1.66,-0.96] | G10: {=_xlfn.XLOOKUP($A10&G$3&$F$2&$A$1,doses_results!$C$2:$C$400&doses_results!$K$2:$K$400&doses_results!$J$2:$J$400&doses_results!$I$2:$I$400,doses_results!$L$2:$L$400,"",0)} -> -1.29[-1.64,-0.94] | H10: {=_xlfn.XLOOKUP($A10&H$3&$C$2&$A$1,doses_results!$C$2:$C$400&doses_results!$K$2:$K$400&doses_results!$J$2:$J$400&doses_results!$I$2:$I$400,doses_results!$L$2:$L$400,"",0)} | I10: {=_xlfn.XLOOKUP($A10&I$3&$I$2&$A$1,doses_results!$C$2:$C$400&doses_results!$K$2:$K$400&doses_results!$J$2:$J$400&doses_results!$I$2:$I$400,doses_results!$L$2:$L$400,"",0)} -> -1.34[-1.69,-1.00] | J10: {=_xlfn.XLOOKUP($A10&J$3&$I$2&$A$1,doses_results!$C$2:$C$400&doses_results!$K$2:$K$400&doses_results!$J$2:$J$400&doses_results!$I$2:$I$400,doses_results!$L$2:$L$400,"",0)} -> -1.07[-1.39,-0.75]
A11: prop_other | B11: Proportion Other Ethnicity | C11: {=_xlfn.XLOOKUP($A11&C$3&$C$2&$A$1,doses_results!$C$2:$C$400&doses_results!$K$2:$K$400&doses_results!$J$2:$J$400&doses_results!$I$2:$I$400,doses_results!$L$2:$L$400,"",0)} -> -0.02[-0.43,0.39] | D11: {=_xlfn.XLOOKUP($A11&D$3&$C$2&$A$1,doses_results!$C$2:$C$400&doses_results!$K$2:$K$400&doses_results!$J$2:$J$400&doses_results!$I$2:$I$400,doses_results!$L$2:$L$400,"",0)} -> -0.03[-0.45,0.38] | E11: {=_xlfn.XLOOKUP($A11&E$3&$C$2&$A$1,doses_results!$C$2:$C$400&doses_results!$K$2:$K$400&doses_results!$J$2:$J$400&doses_results!$I$2:$I$400,doses_results!$L$2:$L$400,"",0)} | F11: {=_xlfn.XLOOKUP($A11&F$3&$F$2&$A$1,doses_results!$C$2:$C$400&doses_results!$K$2:$K$400&doses_results!$J$2:$J$400&doses_results!$I$2:$I$400,doses_results!$L$2:$L$400,"",0)} | G11: {=_xlfn.XLOOKUP($A11&G$3&$F$2&$A$1,doses_results!$C$2:$C$400&doses_results!$K$2:$K$400&doses_results!$J$2:$J$400&doses_results!$I$2:$I$400,doses_results!$L$2:$L$400,"",0)} | H11: {=_xlfn.XLOOKUP($A11&H$3&$C$2&$A$1,doses_results!$C$2:$C$400&doses_results!$K$2:$K$400&doses_results!$J$2:$J$400&doses_results!$I$2:$I$400,doses_results!$L$2:$L$400,"",0)} | I11: {=_xlfn.XLOOKUP($A11&I$3&$I$2&$A$1,doses_results!$C$2:$C$400&doses_results!$K$2:$K$400&doses_results!$J$2:$J$400&doses_results!$I$2:$I$400,doses_results!$L$2:$L$400,"",0)} | J11: {=_xlfn.XLOOKUP($A11&J$3&$I$2&$A$1,doses_results!$C$2:$C$400&doses_results!$K$2:$K$400&doses_results!$J$2:$J$400&doses_results!$I$2:$I$400,doses_results!$L$2:$L$400,"",0)}
A12: IMD_Average_score | B12: IMD Average Score | C12: {=_xlfn.XLOOKUP($A12&C$3&$C$2&$A$1,doses_results!$C$2:$C$400&doses_results!$K$2:$K$400&doses_results!$J$2:$J$400&doses_results!$I$2:$I$400,doses_results!$L$2:$L$400,"",0)} -> 0.11[-1.36,1.58] | D12: {=_xlfn.XLOOKUP($A12&D$3&$C$2&$A$1,doses_results!$C$2:$C$400&doses_results!$K$2:$K$400&doses_results!$J$2:$J$400&doses_results!$I$2:$I$400,doses_results!$L$2:$L$400,"",0)} -> 0.12[-1.35,1.60] | E12: {=_xlfn.XLOOKUP($A12&E$3&$C$2&$A$1,doses_results!$C$2:$C$400&doses_results!$K$2:$K$400&doses_results!$J$2:$J$400&doses_results!$I$2:$I$400,doses_results!$L$2:$L$400,"",0)} | F12: {=_xlfn.XLOOKUP($A12&F$3&$F$2&$A$1,doses_results!$C$2:$C$400&doses_results!$K$2:$K$400&doses_results!$J$2:$J$400&doses_results!$I$2:$I$400,doses_results!$L$2:$L$400,"",0)} -> -0.29[-1.35,0.77] | G12: {=_xlfn.XLOOKUP($A12&G$3&$F$2&$A$1,doses_results!$C$2:$C$400&doses_results!$K$2:$K$400&doses_results!$J$2:$J$400&doses_results!$I$2:$I$400,doses_results!$L$2:$L$400,"",0)} -> -0.26[-1.32,0.80] | H12: {=_xlfn.XLOOKUP($A12&H$3&$C$2&$A$1,doses_results!$C$2:$C$400&doses_results!$K$2:$K$400&doses_results!$J$2:$J$400&doses_results!$I$2:$I$400,doses_results!$L$2:$L$400,"",0)} | I12: {=_xlfn.XLOOKUP($A12&I$3&$I$2&$A$1,doses_results!$C$2:$C$400&doses_results!$K$2:$K$400&doses_results!$J$2:$J$400&doses_results!$I$2:$I$400,doses_results!$L$2:$L$400,"",0)} | J12: {=_xlfn.XLOOKUP($A12&J$3&$I$2&$A$1,doses_results!$C$2:$C$400&doses_results!$K$2:$K$400&doses_results!$J$2:$J$400&doses_results!$I$2:$I$400,doses_results!$L$2:$L$400,"",0)}
A13: prop_o65 | B13: Proportion Over 65 | C13: {=_xlfn.XLOOKUP($A13&C$3&$C$2&$A$1,doses_results!$C$2:$C$400&doses_results!$K$2:$K$400&doses_results!$J$2:$J$400&doses_results!$I$2:$I$400,doses_results!$L$2:$L$400,"",0)} -> 0.76[-0.15,1.68] | D13: {=_xlfn.XLOOKUP($A13&D$3&$C$2&$A$1,doses_results!$C$2:$C$400&doses_results!$K$2:$K$400&doses_results!$J$2:$J$400&doses_results!$I$2:$I$400,doses_results!$L$2:$L$400,"",0)} -> 0.81[-0.12,1.75] | E13: {=_xlfn.XLOOKUP($A13&E$3&$C$2&$A$1,doses_results!$C$2:$C$400&doses_results!$K$2:$K$400&doses_results!$J$2:$J$400&doses_results!$I$2:$I$400,doses_results!$L$2:$L$400,"",0)} | F13: {=_xlfn.XLOOKUP($A13&F$3&$F$2&$A$1,doses_results!$C$2:$C$400&doses_results!$K$2:$K$400&doses_results!$J$2:$J$400&doses_results!$I$2:$I$400,doses_results!$L$2:$L$400,"",0)} -> -1.20[-2.30,-0.10] | G13: {=_xlfn.XLOOKUP($A13&G$3&$F$2&$A$1,doses_results!$C$2:$C$400&doses_results!$K$2:$K$400&doses_results!$J$2:$J$400&doses_results!$I$2:$I$400,doses_results!$L$2:$L$400,"",0)} -> -1.17[-2.29,-0.06] | H13: {=_xlfn.XLOOKUP($A13&H$3&$C$2&$A$1,doses_results!$C$2:$C$400&doses_results!$K$2:$K$400&doses_results!$J$2:$J$400&doses_results!$I$2:$I$400,doses_results!$L$2:$L$400,"",0)} | I13: {=_xlfn.XLOOKUP($A13&I$3&$I$2&$A$1,doses_results!$C$2:$C$400&doses_results!$K$2:$K$400&doses_results!$J$2:$J$400&doses_results!$I$2:$I$400,doses_results!$L$2:$L$400,"",0)} -> -1.58[-2.37,-0.80] | J13: {=_xlfn.XLOOKUP($A13&J$3&$I$2&$A$1,doses_results!$C$2:$C$400&doses_results!$K$2:$K$400&doses_results!$J$2:$J$400&doses_results!$I$2:$I$400,doses_results!$L$2:$L$400,"",0)}
A14: prop_u25 | B14: Proportion Under 25 | C14: {=_xlfn.XLOOKUP($A14&C$3&$C$2&$A$1,doses_results!$C$2:$C$400&doses_results!$K$2:$K$400&doses_results!$J$2:$J$400&doses_results!$I$2:$I$400,doses_results!$L$2:$L$400,"",0)} -> -1.49[-2.15,-0.84] | D14: {=_xlfn.XLOOKUP($A14&D$3&$C$2&$A$1,doses_results!$C$2:$C$400&doses_results!$K$2:$K$400&doses_results!$J$2:$J$400&doses_results!$I$2:$I$400,doses_results!$L$2:$L$400,"",0)} -> -1.46[-2.14,-0.79] | E14: {=_xlfn.XLOOKUP($A14&E$3&$C$2&$A$1,doses_results!$C$2:$C$400&doses_results!$K$2:$K$400&doses_results!$J$2:$J$400&doses_results!$I$2:$I$400,doses_results!$L$2:$L$400,"",0)} | F14: {=_xlfn.XLOOKUP($A14&F$3&$F$2&$A$1,doses_results!$C$2:$C$400&doses_results!$K$2:$K$400&doses_results!$J$2:$J$400&doses_results!$I$2:$I$400,doses_results!$L$2:$L$400,"",0)} -> -0.42[-1.23,0.40] | G14: {=_xlfn.XLOOKUP($A14&G$3&$F$2&$A$1,doses_results!$C$2:$C$400&doses_results!$K$2:$K$400&doses_results!$J$2:$J$400&doses_results!$I$2:$I$400,doses_results!$L$2:$L$400,"",0)} -> -0.46[-1.30,0.38] | H14: {=_xlfn.XLOOKUP($A14&H$3&$C$2&$A$1,doses_results!$C$2:$C$400&doses_results!$K$2:$K$400&doses_results!$J$2:$J$400&doses_results!$I$2:$I$400,doses_results!$L$2:$L$400,"",0)} | I14: {=_xlfn.XLOOKUP($A14&I$3&$I$2&$A$1,doses_results!$C$2:$C$400&doses_results!$K$2:$K$400&doses_results!$J$2:$J$400&doses_results!$I$2:$I$400,doses_results!$L$2:$L$400,"",0)} | J14: {=_xlfn.XLOOKUP($A14&J$3&$I$2&$A$1,doses_results!$C$2:$C$400&doses_results!$K$2:$K$400&doses_results!$J$2:$J$400&doses_results!$I$2:$I$400,doses_results!$L$2:$L$400,"",0)}
A15: Median_annual_income | B15: Median Annual Income | C15: {=_xlfn.XLOOKUP($A15&C$3&$C$2&$A$1,doses_results!$C$2:$C$400&doses_results!$K$2:$K$400&doses_results!$J$2:$J$400&doses_results!$I$2:$I$400,doses_results!$L$2:$L$400,"",0)} -> -0.24[-0.57,0.09] | D15: {=_xlfn.XLOOKUP($A15&D$3&$C$2&$A$1,doses_results!$C$2:$C$400&doses_results!$K$2:$K$400&doses_results!$J$2:$J$400&doses_results!$I$2:$I$400,doses_results!$L$2:$L$400,"",0)} -> -0.23[-0.56,0.11] | E15: {=_xlfn.XLOOKUP($A15&E$3&$C$2&$A$1,doses_results!$C$2:$C$400&doses_results!$K$2:$K$400&doses_results!$J$2:$J$400&doses_results!$I$2:$I$400,doses_results!$L$2:$L$400,"",0)} | F15: {=_xlfn.XLOOKUP($A15&F$3&$F$2&$A$1,doses_results!$C$2:$C$400&doses_results!$K$2:$K$400&doses_results!$J$2:$J$400&doses_results!$I$2:$I$400,doses_results!$L$2:$L$400,"",0)} | G15: {=_xlfn.XLOOKUP($A15&G$3&$F$2&$A$1,doses_results!$C$2:$C$400&doses_results!$K$2:$K$400&doses_results!$J$2:$J$400&doses_results!$I$2:$I$400,doses_results!$L$2:$L$400,"",0)} | H15: {=_xlfn.XLOOKUP($A15&H$3&$C$2&$A$1,doses_results!$C$2:$C$400&doses_results!$K$2:$K$400&doses_results!$J$2:$J$400&doses_results!$I$2:$I$400,doses_results!$L$2:$L$400,"",0)} | I15: {=_xlfn.XLOOKUP($A15&I$3&$I$2&$A$1,doses_results!$C$2:$C$400&doses_results!$K$2:$K$400&doses_results!$J$2:$J$400&doses_results!$I$2:$I$400,doses_results!$L$2:$L$400,"",0)} | J15: {=_xlfn.XLOOKUP($A15&J$3&$I$2&$A$1,doses_results!$C$2:$C$400&doses_results!$K$2:$K$400&doses_results!$J$2:$J$400&doses_results!$I$2:$I$400,doses_results!$L$2:$L$400,"",0)}
... A35: ASC_rapid_testing | B35: ASC Rapid Testing | C35: {=_xlfn.XLOOKUP($A35&C$3&$C$2&$A$1,doses_results!$C$2:$C$400&doses_results!$K$2:$K$400&doses_results!$J$2:$J$400&doses_results!$I$2:$I$400,doses_results!$L$2:$L$400,"",0)} | D35: {=_xlfn.XLOOKUP($A35&D$3&$C$2&$A$1,doses_results!$C$2:$C$400&doses_results!$K$2:$K$400&doses_results!$J$2:$J$400&doses_results!$I$2:$I$400,doses_results!$L$2:$L$400,"",0)} | E35: {=_xlfn.XLOOKUP($A35&E$3&$C$2&$A$1,doses_results!$C$2:$C$400&doses_results!$K$2:$K$400&doses_results!$J$2:$J$400&doses_results!$I$2:$I$400,doses_results!$L$2:$L$400,"",0)} | F35: {=_xlfn.XLOOKUP($A35&F$3&$F$2&$A$1,doses_results!$C$2:$C$400&doses_results!$K$2:$K$400&doses_results!$J$2:$J$400&doses_results!$I$2:$I$400,doses_results!$L$2:$L$400,"",0)} | G35: {=_xlfn.XLOOKUP($A35&G$3&$F$2&$A$1,doses_results!$C$2:$C$400&doses_results!$K$2:$K$400&doses_results!$J$2:$J$400&doses_results!$I$2:$I$400,doses_results!$L$2:$L$400,"",0)} | H35: {=_xlfn.XLOOKUP($A35&H$3&$C$2&$A$1,doses_results!$C$2:$C$400&doses_results!$K$2:$K$400&doses_results!$J$2:$J$400&doses_results!$I$2:$I$400,doses_results!$L$2:$L$400,"",0)} | I35: {=_xlfn.XLOOKUP($A35&I$3&$I$2&$A$1,doses_results!$C$2:$C$400&doses_results!$K$2:$K$400&doses_results!$J$2:$J$400&doses_results!$I$2:$I$400,doses_results!$L$2:$L$400,"",0)} | J35: {=_xlfn.XLOOKUP($A35&J$3&$I$2&$A$1,doses_results!$C$2:$C$400&doses_results!$K$2:$K$400&doses_results!$J$2:$J$400&doses_results!$I$2:$I$400,doses_results!$L$2:$L$400,"",0)} -> 1.20[0.02,2.38]

Sheet third_dose_table
A1: Third
C2: Simple | F2: Lasso | I2: Stepwise
A3: Variable | B3: Variable | C3: Fixed | D3: Random | F3: Fixed | G3: Random | I3: Fixed | J3: Random
A4: Pop_per_km2 | B4: Population per km2 | C4: {=_xlfn.XLOOKUP($A4&C$3&$C$2&$A$1,doses_results!$C$2:$C$400&doses_results!$K$2:$K$400&doses_results!$J$2:$J$400&doses_results!$I$2:$I$400,doses_results!$L$2:$L$400,"",0)} -> 0.61[0.02,1.19] | D4: {=_xlfn.XLOOKUP($A4&D$3&$C$2&$A$1,doses_results!$C$2:$C$400&doses_results!$K$2:$K$400&doses_results!$J$2:$J$400&doses_results!$I$2:$I$400,doses_results!$L$2:$L$400,"",0)} -> 0.45[-0.13,1.04] | E4: {=_xlfn.XLOOKUP($A4&E$3&$C$2&$A$1,doses_results!$C$2:$C$400&doses_results!$K$2:$K$400&doses_results!$J$2:$J$400&doses_results!$I$2:$I$400,doses_results!$L$2:$L$400,"",0)} | F4: {=_xlfn.XLOOKUP($A4&F$3&$F$2&$A$1,doses_results!$C$2:$C$400&doses_results!$K$2:$K$400&doses_results!$J$2:$J$400&doses_results!$I$2:$I$400,doses_results!$L$2:$L$400,"",0)} -> -21.13[-39.07,-3.19] | G4: {=_xlfn.XLOOKUP($A4&G$3&$F$2&$A$1,doses_results!$C$2:$C$400&doses_results!$K$2:$K$400&doses_results!$J$2:$J$400&doses_results!$I$2:$I$400,doses_results!$L$2:$L$400,"",0)} -> -18.83[-36.55,-1.10] | H4: {=_xlfn.XLOOKUP($A4&H$3&$C$2&$A$1,doses_results!$C$2:$C$400&doses_results!$K$2:$K$400&doses_results!$J$2:$J$400&doses_results!$I$2:$I$400,doses_results!$L$2:$L$400,"",0)} | I4: {=_xlfn.XLOOKUP($A4&I$3&$I$2&$A$1,doses_results!$C$2:$C$400&doses_results!$K$2:$K$400&doses_results!$J$2:$J$400&doses_results!$I$2:$I$400,doses_results!$L$2:$L$400,"",0)} -> -16.76[-33.66,0.13] | J4: {=_xlfn.XLOOKUP($A4&J$3&$I$2&$A$1,doses_results!$C$2:$C$400&doses_results!$K$2:$K$400&doses_results!$J$2:$J$400&doses_results!$I$2:$I$400,doses_results!$L$2:$L$400,"",0)}
A5: prop_travelling_to_work | B5: Proportion Travelling To Work | C5: {=_xlfn.XLOOKUP($A5&C$3&$C$2&$A$1,doses_results!$C$2:$C$400&doses_results!$K$2:$K$400&doses_results!$J$2:$J$400&doses_results!$I$2:$I$400,doses_results!$L$2:$L$400,"",0)} -> -1.07[-2.38,0.25] | D5: {=_xlfn.XLOOKUP($A5&D$3&$C$2&$A$1,doses_results!$C$2:$C$400&doses_results!$K$2:$K$400&doses_results!$J$2:$J$400&doses_results!$I$2:$I$400,doses_results!$L$2:$L$400,"",0)} -> -0.80[-2.11,0.52] | E5: {=_xlfn.XLOOKUP($A5&E$3&$C$2&$A$1,doses_results!$C$2:$C$400&doses_results!$K$2:$K$400&doses_results!$J$2:$J$400&doses_results!$I$2:$I$400,doses_results!$L$2:$L$400,"",0)} | F5: {=_xlfn.XLOOKUP($A5&F$3&$F$2&$A$1,doses_results!$C$2:$C$400&doses_results!$K$2:$K$400&doses_results!$J$2:$J$400&doses_results!$I$2:$I$400,doses_results!$L$2:$L$400,"",0)} | G5: {=_xlfn.XLOOKUP($A5&G$3&$F$2&$A$1,doses_results!$C$2:$C$400&doses_results!$K$2:$K$400&doses_results!$J$2:$J$400&doses_results!$I$2:$I$400,doses_results!$L$2:$L$400,"",0)} | H5: {=_xlfn.XLOOKUP($A5&H$3&$C$2&$A$1,doses_results!$C$2:$C$400&doses_results!$K$2:$K$400&doses_results!$J$2:$J$400&doses_results!$I$2:$I$400,doses_results!$L$2:$L$400,"",0)} | I5: {=_xlfn.XLOOKUP($A5&I$3&$I$2&$A$1,doses_results!$C$2:$C$400&doses_results!$K$2:$K$400&doses_results!$J$2:$J$400&doses_results!$I$2:$I$400,doses_results!$L$2:$L$400,"",0)} | J5: {=_xlfn.XLOOKUP($A5&J$3&$I$2&$A$1,doses_results!$C$2:$C$400&doses_results!$K$2:$K$400&doses_results!$J$2:$J$400&doses_results!$I$2:$I$400,doses_results!$L$2:$L$400,"",0)} -> -0.04[-0.41,0.34]
A6: prop_not_in_work | B6: Proportion Not In Work | C6: {=_xlfn.XLOOKUP($A6&C$3&$C$2&$A$1,doses_results!$C$2:$C$400&doses_results!$K$2:$K$400&doses_results!$J$2:$J$400&doses_results!$I$2:$I$400,doses_results!$L$2:$L$400,"",0)} -> -1.67[-3.29,-0.05] | D6: {=_xlfn.XLOOKUP($A6&D$3&$C$2&$A$1,doses_results!$C$2:$C$400&doses_results!$K$2:$K$400&doses_results!$J$2:$J$400&doses_results!$I$2:$I$400,doses_results!$L$2:$L$400,"",0)} -> -1.59[-3.24,0.05] | E6: {=_xlfn.XLOOKUP($A6&E$3&$C$2&$A$1,doses_results!$C$2:$C$400&doses_results!$K$2:$K$400&doses_results!$J$2:$J$400&doses_results!$I$2:$I$400,doses_results!$L$2:$L$400,"",0)} | F6: {=_xlfn.XLOOKUP($A6&F$3&$F$2&$A$1,doses_results!$C$2:$C$400&doses_results!$K$2:$K$400&doses_results!$J$2:$J$400&doses_results!$I$2:$I$400,doses_results!$L$2:$L$400,"",0)} -> 0.04[-0.64,0.73] | G6: {=_xlfn.XLOOKUP($A6&G$3&$F$2&$A$1,doses_results!$C$2:$C$400&doses_results!$K$2:$K$400&doses_results!$J$2:$J$400&doses_results!$I$2:$I$400,doses_results!$L$2:$L$400,"",0)} -> -0.03[-0.73,0.68] | H6: {=_xlfn.XLOOKUP($A6&H$3&$C$2&$A$1,doses_results!$C$2:$C$400&doses_results!$K$2:$K$400&doses_results!$J$2:$J$400&doses_results!$I$2:$I$400,doses_results!$L$2:$L$400,"",0)} | I6: {=_xlfn.XLOOKUP($A6&I$3&$I$2&$A$1,doses_results!$C$2:$C$400&doses_results!$K$2:$K$400&doses_results!$J$2:$J$400&doses_results!$I$2:$I$400,doses_results!$L$2:$L$400,"",0)} | J6: {=_xlfn.XLOOKUP($A6&J$3&$I$2&$A$1,doses_results!$C$2:$C$400&doses_results!$K$2:$K$400&doses_results!$J$2:$J$400&doses_results!$I$2:$I$400,doses_results!$L$2:$L$400,"",0)}
